Workbook
Name AgrID: 'Executive Summary'!$L$6
Name AgrType: 'Executive Summary'!$C$9
Name AnnBaseRebate: 'Executive Summary'!$J$36
Name AnnualBase: #REF!
Name AnnualBasePct: #REF!
Name AnnualFocus: 'Executive Summary'!$K$36
Name AnnualGrowth: #REF!
Name AsOf: #REF!
Name Baseline: 'Executive Summary'!$E$36
Name BaseRebate: 'Executive Summary'!$I$43
Name beneficiary: 'Executive Summary'!$C$5
Name CustomerName: #REF!
Name DetailPayment: #REF!
Name EndMonth: 'Executive Summary'!$D$8
Name GrowMinReq: 'Executive Summary'!$H$47
Name Growth_075: 'Executive Summary'!$I$47
Name Growth_10: 'Executive Summary'!$I$48
Name GrowthPct: #REF!
Name GrowthRebate: 'Executive Summary'!$L$36
Name Payment: 'Executive Summary'!$M$36
Name SemiAnnRebate: 'Executive Summary'!$H$36
Name SemiBase: #REF!
Name SemiBasePct: #REF!
Name SemiFocusRebate: 'Executive Summary'!$I$36
Name TimePeriod: #REF!
Name Variance: 'Executive Summary'!$F$36
Name VarPct: 'Executive Summary'!$G$36

Sheet How To
A1: Start in DetailExport Tab
B3: 1 | C3: Copy IDN info from Database by running button for "My Contracts" or "All Active Contracts". Find the appropriate Agr ID, copy entire row in and paste in row 1 including the header.
B7: 1
B20: 2 | C20: click anywhere in the table and in your ribbon go to: Table Design
C21: click the dropdown under "Refresh"
C22: select "Connect Properties"
C23: select the "Definition" tab and
C24: scroll down in the "Command Text" section and replace IDN with current IDN Name

Sheet Executive Summary
K1: Business Analyst: | L1: Daysi Garcia
B2: BECTON DICKINSON
B3: Strategic Collaboration Agreement
B4: Executive Overview
B5: Account: | C5: MONTEFIORE HEALTH SYSTEM | K5: Account Manager: | L5: Mary Inguanti
B6: Incentive Term: | C6: Jan2023 to Dec2025 | K6: Agr ID: | L6: 4808
C7: 36 | D7: Months
B8: Current Reporting Period: | C8: 45680 | D8: 46022
B9: Incentive Type: | C9: Strategic Collaboration Agreement
B10: Year: | C10: 3
B12: Comments/Considerations
B13: Products defined on Schedule B and subject to BDX General Terms
B14: Eligible facilities are limited to membership as defined on Schedule 1
D16: =TEXT(C8,"mmm-y")&" to "&TEXT(D8,"mmm-yy") -> Jan-25 to Dec-25 | E16: =TEXT(EDATE(C8,-12),"mmm-y")&" to "&TEXT(EDATE(D8,-12),"mmm-yy") -> Jan-24 to Dec-24 | H16: =IF(Variance<=0,0,VLOOKUP(VarPct,H43:I43,2)) -> 0.015 | I16: =IF(COUNTIFS(C19:C35,"Focus*",F19:F35,"<0")=0,J43,0) -> 0 | J16: =IF(MONTH(EndMonth)<=6,"",IF(Variance<=0,0,VLOOKUP(G36,H43:I43,2))) -> 0.015 | K16: =IF(MONTH(EndMonth)<=6,0,IF(COUNTIFS(C19:C35,"Focus*",F19:F35,"<0")=0,J43,0)) -> 0 | L16: =IF(MONTH(EndMonth)<=6,"",IF(VarPct<=GrowMinReq,0,VLOOKUP(G36,H47:I48,2))) -> 0.1 | M16: =IF(MONTH(D8)=6,"Semi-Annual","")
H17: Semi-Annual Rebate | J17: Annualized Rebate minus Semi Annual Rebate
B18: Business Segment | C18: Category | F18: $ Variance | G18: % Variance | H18: Base Rebate | I18: Focus Rebate | J18: =I41 -> Base Rebate | K18: Focus Rebate | L18: Growth Rebate | M18: Rebate Total
B19: Diagnostic Solutions | C19: Base | D19: 1561023.6 | E19: 1928480.7 | F19: =D19-E19 -> -367457.1 | G19: =F19/E19 -> -0.19054227 | H19: 14721.572 | J19: =IF(MONTH(EndMonth)<=6,0,IFERROR($J$16*E19-H19,"")) -> 14205.639 | K19: =IF(MONTH(EndMonth)<=6,"",IF(C19="Base","",IFERROR(ROUND(E19*$K$16-I19,2),""))) | L19: =IF(MONTH(EndMonth)<=6,"",IF(MONTH($D$8)=6,"",IF(F19<=0,0,(F19/SUMIFS($F$19:$F$31,$F$19:$F$31,">0"))*$L$36))) -> 0 | M19: =IF(MONTH(EndMonth)<12,SUM(H19:I19),SUM(J19:L19)) -> 14205.639
B20: Medication Delivery Solutions | C20: Base | D20: 7292563.8 | E20: 6627820.9 | F20: =D20-E20 -> 664742.9 | G20: =F20/E20 -> 0.10029585 | H20: 48944.06 | J20: =IF(MONTH(EndMonth)<=6,0,IFERROR($J$16*E20-H20,"")) -> 50473.254 | K20: =IF(MONTH(EndMonth)<=6,"",IF(C20="Base","",IFERROR(ROUND(E20*$K$16-I20,2),""))) | L20: =IF(MONTH(EndMonth)<=6,"",IF(MONTH($D$8)=6,"",IF(F20<=0,0,(F20/SUMIFS($F$19:$F$31,$F$19:$F$31,">0"))*$L$36))) -> 59334.404 | M20: =IF(MONTH(EndMonth)<12,SUM(H20:I20),SUM(J20:L20)) -> 109807.66
C21: Focus Conventional Hypodermic | D21: 459798.14 | E21: 422633.21 | F21: =D21-E21 -> 37164.93 | G21: =F21/E21 -> 0.087936606 | H21: 3187.8186 | I21: 0 | J21: =IF(MONTH(EndMonth)<=6,0,IFERROR($J$16*E21-H21,"")) -> 3151.6796 | K21: =IF(MONTH(EndMonth)<=6,"",IF(C21="Base","",IFERROR(ROUND(E21*$K$16-I21,2),""))) -> 0 | L21: =IF(MONTH(EndMonth)<=6,"",IF(MONTH($D$8)=6,"",IF(F21<=0,0,(F21/SUMIFS($F$19:$F$31,$F$19:$F$31,">0"))*$L$36))) -> 3317.311 | M21: =IF(MONTH(EndMonth)<12,SUM(H21:I21),SUM(J21:L21)) -> 6468.9906
C22: Focus Safety Hypodermic | D22: 596586.03 | E22: 462212.22 | F22: =D22-E22 -> 134373.81 | G22: =F22/E22 -> 0.29071886 | H22: 2657.512 | I22: 0 | J22: =IF(MONTH(EndMonth)<=6,0,IFERROR($J$16*E22-H22,"")) -> 4275.6713 | K22: =IF(MONTH(EndMonth)<=6,"",IF(C22="Base","",IFERROR(ROUND(E22*$K$16-I22,2),""))) -> 0 | L22: =IF(MONTH(EndMonth)<=6,"",IF(MONTH($D$8)=6,"",IF(F22<=0,0,(F22/SUMIFS($F$19:$F$31,$F$19:$F$31,">0"))*$L$36))) -> 11994.096 | M22: =IF(MONTH(EndMonth)<12,SUM(H22:I22),SUM(J22:L22)) -> 16269.767
C23: Focus Prefilled Flush | D23: 949258.14 | E23: 949661.39 | F23: =D23-E23 -> -403.25 | G23: =F23/E23 -> -0.00042462503 | H23: 7161.6504 | I23: 0 | J23: =IF(MONTH(EndMonth)<=6,0,IFERROR($J$16*E23-H23,"")) -> 7083.2704 | K23: =IF(MONTH(EndMonth)<=6,"",IF(C23="Base","",IFERROR(ROUND(E23*$K$16-I23,2),""))) -> 0 | L23: =IF(MONTH(EndMonth)<=6,"",IF(MONTH($D$8)=6,"",IF(F23<=0,0,(F23/SUMIFS($F$19:$F$31,$F$19:$F$31,">0"))*$L$36))) -> 0 | M23: =IF(MONTH(EndMonth)<12,SUM(H23:I23),SUM(J23:L23)) -> 7083.2704
B24: Medication Management Solutions | C24: Base | D24: 3646353 | E24: 3320890.4 | F24: =D24-E24 -> 325462.63 | G24: =F24/E24 -> 0.09800463 | H24: 25440.139 | J24: =IF(MONTH(EndMonth)<=6,0,IFERROR($J$16*E24-H24,"")) -> 24373.217 | K24: =IF(MONTH(EndMonth)<=6,"",IF(C24="Base","",IFERROR(ROUND(E24*$K$16-I24,2),""))) | L24: =IF(MONTH(EndMonth)<=6,"",IF(MONTH($D$8)=6,"",IF(F24<=0,0,(F24/SUMIFS($F$19:$F$31,$F$19:$F$31,">0"))*$L$36))) -> 29050.526 | M24: =IF(MONTH(EndMonth)<12,SUM(H24:I24),SUM(J24:L24)) -> 53423.743
B25: Peripheral Intervention | C25: Base | D25: 3136920.2 | E25: 2032920.6 | F25: =D25-E25 -> 1103999.6 | G25: =F25/E25 -> 0.54306083 | H25: 14454.322 | J25: =IF(MONTH(EndMonth)<=6,0,IFERROR($J$16*E25-H25,"")) -> 16039.487 | K25: =IF(MONTH(EndMonth)<=6,"",IF(C25="Base","",IFERROR(ROUND(E25*$K$16-I25,2),""))) | L25: =IF(MONTH(EndMonth)<=6,"",IF(MONTH($D$8)=6,"",IF(F25<=0,0,(F25/SUMIFS($F$19:$F$31,$F$19:$F$31,">0"))*$L$36))) -> 98542.09 | M25: =IF(MONTH(EndMonth)<12,SUM(H25:I25),SUM(J25:L25)) -> 114581.58
B26: Specimen Management | C26: Base | D26: 3742475.5 | E26: 3573198.7 | F26: =D26-E26 -> 169276.78 | G26: =F26/E26 -> 0.047374018 | H26: 26267.415 | J26: =IF(MONTH(EndMonth)<=6,0,IFERROR($J$16*E26-H26,"")) -> 27330.566 | K26: =IF(MONTH(EndMonth)<=6,"",IF(C26="Base","",IFERROR(ROUND(E26*$K$16-I26,2),""))) | L26: =IF(MONTH(EndMonth)<=6,"",IF(MONTH($D$8)=6,"",IF(F26<=0,0,(F26/SUMIFS($F$19:$F$31,$F$19:$F$31,">0"))*$L$36))) -> 15109.506 | M26: =IF(MONTH(EndMonth)<12,SUM(H26:I26),SUM(J26:L26)) -> 42440.072
C27: Focus Specimen Collection | D27: 528991.92 | E27: 521395.42 | F27: =D27-E27 -> 7596.5 | G27: 0 | H27: 3745.3506 | I27: 0 | J27: =IF(MONTH(EndMonth)<=6,0,IFERROR($J$16*E27-H27,"")) -> 4075.5807 | K27: =IF(MONTH(EndMonth)<=6,"",IF(C27="Base","",IFERROR(ROUND(E27*$K$16-I27,2),""))) -> 0 | L27: =IF(MONTH(EndMonth)<=6,"",IF(MONTH($D$8)=6,"",IF(F27<=0,0,(F27/SUMIFS($F$19:$F$31,$F$19:$F$31,">0"))*$L$36))) -> 678.05733 | M27: =IF(MONTH(EndMonth)<12,SUM(H27:I27),SUM(J27:L27)) -> 4753.638
B28: Surgery | C28: Base | D28: 3200775.4 | E28: 2657812.4 | F28: =D28-E28 -> 542963.02 | G28: =F28/E28 -> 0.20428945 | H28: 16306.16 | J28: =IF(MONTH(EndMonth)<=6,0,IFERROR($J$16*E28-H28,"")) -> 23561.026 | K28: =IF(MONTH(EndMonth)<=6,"",IF(C28="Base","",IFERROR(ROUND(E28*$K$16-I28,2),""))) | L28: =IF(MONTH(EndMonth)<=6,"",IF(MONTH($D$8)=6,"",IF(F28<=0,0,(F28/SUMIFS($F$19:$F$31,$F$19:$F$31,">0"))*$L$36))) -> 48464.432 | M28: =IF(MONTH(EndMonth)<12,SUM(H28:I28),SUM(J28:L28)) -> 72025.458
B29: Urology and Critical Care | C29: Base | D29: 1888169.3 | E29: 1766890.9 | F29: =D29-E29 -> 121278.33 | G29: =F29/E29 -> 0.068639398 | H29: 14578.07 | J29: =IF(MONTH(EndMonth)<=6,0,IFERROR($J$16*E29-H29,"")) -> 11925.294 | K29: =IF(MONTH(EndMonth)<=6,"",IF(C29="Base","",IFERROR(ROUND(E29*$K$16-I29,2),""))) | L29: =IF(MONTH(EndMonth)<=6,"",IF(MONTH($D$8)=6,"",IF(F29<=0,0,(F29/SUMIFS($F$19:$F$31,$F$19:$F$31,">0"))*$L$36))) -> 10825.204 | M29: =IF(MONTH(EndMonth)<12,SUM(H29:I29),SUM(J29:L29)) -> 22750.498
C30: Focus Purewick | D30: 2513189.9 | E30: 2208393.6 | F30: =D30-E30 -> 304796.33 | G30: =F30/E30 -> 0.13801722 | H30: 15807.892 | I30: 0 | J30: =IF(MONTH(EndMonth)<=6,0,IFERROR($J$16*E30-H30,"")) -> 17318.011 | K30: =IF(MONTH(EndMonth)<=6,"",IF(C30="Base","",IFERROR(ROUND(E30*$K$16-I30,2),""))) -> 0 | L30: =IF(MONTH(EndMonth)<=6,"",IF(MONTH($D$8)=6,"",IF(F30<=0,0,(F30/SUMIFS($F$19:$F$31,$F$19:$F$31,">0"))*$L$36))) -> 27205.869 | M30: =IF(MONTH(EndMonth)<12,SUM(H30:I30),SUM(J30:L30)) -> 44523.881
C31: Focus Foley Catheters | D31: 67085.22 | E31: 53859.78 | F31: =D31-E31 -> 13225.44 | G31: =F31/E31 -> 0.24555318 | H31: 295.10055 | I31: 0 | J31: =IF(MONTH(EndMonth)<=6,0,IFERROR($J$16*E31-H31,"")) -> 512.79615 | K31: =IF(MONTH(EndMonth)<=6,"",IF(C31="Base","",IFERROR(ROUND(E31*$K$16-I31,2),""))) -> 0 | L31: =IF(MONTH(EndMonth)<=6,"",IF(MONTH($D$8)=6,"",IF(F31<=0,0,(F31/SUMIFS($F$19:$F$31,$F$19:$F$31,">0"))*$L$36))) -> 1180.4919 | M31: =IF(MONTH(EndMonth)<12,SUM(H31:I31),SUM(J31:L31)) -> 1693.288
B36: Grand Total | D36: =SUM(D19:D35) -> 29583190 | E36: =SUM(E19:E35) -> 26526170 | F36: =D36-E36 -> 3057019.9 | G36: =ROUND(F36/E36,4) -> 0.1152 | H36: =SUM(H19:H35) -> 193567.06 | I36: =SUM(I19:I35) -> 0 | J36: =SUM(J19:J35) -> 204325.49 | K36: =SUM(K19:K35) -> 0 | L36: =Variance*L16 -> 305701.99 | M36: =ROUND(SUM(M19:M35),2) -> 510027.48 | N36: =IF(Payment=DetailPayment,"Validated","Check Detail") -> #REF!
B38: Rebate
F41: Minimum Requirement over prior year sales | I41: Base Rebate | J41: Focused Product Rebate
I42: paid on prior year sales | J42: paid on prior year sales of Focused Products
H43: 0 | I43: 0.015 | J43: 0.015
G45: =F41 -> Minimum Requirement over prior year sales | I45: Annual Growth Rebate
I46: paid on incremental sales over prior year
H47: 0.075 | I47: 0.075
H48: 0.1 | I48: 0.1
B52: Incentive History
B53: Rebate Period | C53: End | D53: Agr Year | E53: Curr Sales | F53: Prior Sales | G53: Var $ | H53: Var % | I53: Base Rebate | J53: Focus Rebate | K53: =L18 -> Growth Rebate | L53: Total Incentive | M53: Var% over PY
...

Sheet AcctReport
A1: ='Executive Summary'!B3 -> Strategic Collaboration Agreement
A2: =beneficiary -> MONTEFIORE HEALTH SYSTEM
A3: From | B3: {=TRANSPOSE(_xlfn.ANCHORARRAY('Executive Summary'!C8))} -> #REF! | L3: {='Executive Summary'!H16:L16} -> 0.015 | M3: 0 | N3: 0.015 | O3: 0 | P3: 0.1
A4: To | H4: Total from Executive Summary | I4: ='Executive Summary'!D36 -> 29583190 | J4: ='Executive Summary'!E36 -> 26526170 | K4: =I4-J4 -> 3057019.9 | L4: =IF(MONTH(EndMonth)=12,0,'Executive Summary'!H36) -> 0 | M4: =IF(MONTH(EndMonth)=12,0,'Executive Summary'!I36) -> 0 | N4: {='Executive Summary'!J36:L36} -> 204325.49 | O4: 0 | P4: 305701.99 | Q4: =ROUND(SUM(L4:P4),2) -> 510027.48
I5: =SUM(I7:I476) -> 29583190 | J5: =SUM(J6:J476) -> 26526170 | K5: =SUM(K6:K476) -> 3057019.9 | L5: =SUM(L6:L476) -> 0 | M5: =SUM(M6:M476) -> 0 | N5: =SUM(N6:N476) -> 204325.49 | O5: =SUM(O6:O476) -> 0 | P5: =SUM(P6:P476) -> 305701.99 | Q5: =ROUND(SUM(Q6:Q476),2) -> 510027.48
A6: Strategic IDN | B6: Strategic Division | C6: Survivor# | D6: Name | E6: Address | F6: City | G6: ST | H6: Zip | I6: Current | J6: Prior | K6: Variance | L6: Semi-Annual Base | M6: Semi-Annual Focus Rebate | N6: Base Rebate | O6: Annual Focus Rebate | P6: Growth Rebate | Q6: Rebate
A7: {=_xlfn._xlws.SORT(_xlfn.UNIQUE(MasterData[[Strategic IDN]:[Survivor Postal Code]]))} -> MONTEFIORE HEALTH SYSTEM | B7: MONTEFIORE HEALTH SYSTEM | C7: 1001000635 | D7: CORNWALL HOSPITAL | E7: 19 LAUREL AVE | F7: CORNWALL | G7: NY | H7: 12518 | I7: =SUMIFS(MasterData[Curr Sales],MasterData[Survivor Customer'#],AcctReport!C7) -> 22385.05 | J7: =SUMIFS(MasterData[Prior Sales],MasterData[Survivor Customer'#],AcctReport!C7) -> 16818.07 | K7: =+I7-J7 -> 5566.98 | L7: =SUMIFS(MasterData[Semi-Annual Base],MasterData[Survivor Customer'#],AcctReport!C7) -> 0 | M7: =SUMIFS(MasterData[Semi-Annual Focus],MasterData[Survivor Customer'#],AcctReport!C7) -> 0 | N7: =SUMIFS(MasterData[Base Rebate],MasterData[Survivor Customer'#],AcctReport!C7) -> 129.54604 | O7: =SUMIFS(MasterData[Annual Focus],MasterData[Survivor Customer'#],AcctReport!C7) -> 0 | P7: =SUMIFS(MasterData[Growth Rebate],MasterData[Survivor Customer'#],AcctReport!C7) -> 556.698 | Q7: =SUM(L7:P7) -> 686.24404
A8: MONTEFIORE HEALTH SYSTEM | B8: MONTEFIORE HEALTH SYSTEM | C8: 1001000649 | D8: MONTEFIORE HOSPITAL MEDICAL CENTER | E8: 111 E 210TH ST | F8: BRONX | G8: NY | H8: 10467 | I8: =SUMIFS(MasterData[Curr Sales],MasterData[Survivor Customer'#],AcctReport!C8) -> 12253325 | J8: =SUMIFS(MasterData[Prior Sales],MasterData[Survivor Customer'#],AcctReport!C8) -> 10930966 | K8: =+I8-J8 -> 1322359.5 | L8: =SUMIFS(MasterData[Semi-Annual Base],MasterData[Survivor Customer'#],AcctReport!C8) -> 0 | M8: =SUMIFS(MasterData[Semi-Annual Focus],MasterData[Survivor Customer'#],AcctReport!C8) -> 0 | N8: =SUMIFS(MasterData[Base Rebate],MasterData[Survivor Customer'#],AcctReport!C8) -> 84198.924 | O8: =SUMIFS(MasterData[Annual Focus],MasterData[Survivor Customer'#],AcctReport!C8) -> 0 | P8: =SUMIFS(MasterData[Growth Rebate],MasterData[Survivor Customer'#],AcctReport!C8) -> 132235.95 | Q8: =SUM(L8:P8) -> 216434.87
A9: MONTEFIORE HEALTH SYSTEM | B9: MONTEFIORE HEALTH SYSTEM | C9: 1001000662 | D9: ST LUKES HOSPITAL | E9: 70 DUBOIS ST | F9: NEWBURGH | G9: NY | H9: 12550 | I9: =SUMIFS(MasterData[Curr Sales],MasterData[Survivor Customer'#],AcctReport!C9) -> 1818878.3 | J9: =SUMIFS(MasterData[Prior Sales],MasterData[Survivor Customer'#],AcctReport!C9) -> 1796223.9 | K9: =+I9-J9 -> 22654.37 | L9: =SUMIFS(MasterData[Semi-Annual Base],MasterData[Survivor Customer'#],AcctReport!C9) -> 0 | M9: =SUMIFS(MasterData[Semi-Annual Focus],MasterData[Survivor Customer'#],AcctReport!C9) -> 0 | N9: =SUMIFS(MasterData[Base Rebate],MasterData[Survivor Customer'#],AcctReport!C9) -> 13835.934 | O9: =SUMIFS(MasterData[Annual Focus],MasterData[Survivor Customer'#],AcctReport!C9) -> 0 | P9: =SUMIFS(MasterData[Growth Rebate],MasterData[Survivor Customer'#],AcctReport!C9) -> 2265.437 | Q9: =SUM(L9:P9) -> 16101.371
A10: MONTEFIORE HEALTH SYSTEM | B10: MONTEFIORE HEALTH SYSTEM | C10: 1001000671 | D10: WHITE PLAINS HOSPITAL CENTER | E10: 41 E POST RD | F10: WHITE PLAINS | G10: NY | H10: 10601 | I10: =SUMIFS(MasterData[Curr Sales],MasterData[Survivor Customer'#],AcctReport!C10) -> 4621477.3 | J10: =SUMIFS(MasterData[Prior Sales],MasterData[Survivor Customer'#],AcctReport!C10) -> 4058024.2 | K10: =+I10-J10 -> 563453.15 | L10: =SUMIFS(MasterData[Semi-Annual Base],MasterData[Survivor Customer'#],AcctReport!C10) -> 0 | M10: =SUMIFS(MasterData[Semi-Annual Focus],MasterData[Survivor Customer'#],AcctReport!C10) -> 0 | N10: =SUMIFS(MasterData[Base Rebate],MasterData[Survivor Customer'#],AcctReport!C10) -> 31258.104 | O10: =SUMIFS(MasterData[Annual Focus],MasterData[Survivor Customer'#],AcctReport!C10) -> 0 | P10: =SUMIFS(MasterData[Growth Rebate],MasterData[Survivor Customer'#],AcctReport!C10) -> 56345.315 | Q10: =SUM(L10:P10) -> 87603.419
A11: MONTEFIORE HEALTH SYSTEM | B11: MONTEFIORE HEALTH SYSTEM | C11: 1001001124 | D11: MT VERNON HOSPITAL | E11: 12 N 7TH AVE | F11: MOUNT VERNON | G11: NY | H11: 10550 | I11: =SUMIFS(MasterData[Curr Sales],MasterData[Survivor Customer'#],AcctReport!C11) -> 231200.44 | J11: =SUMIFS(MasterData[Prior Sales],MasterData[Survivor Customer'#],AcctReport!C11) -> 197298.68 | K11: =+I11-J11 -> 33901.76 | L11: =SUMIFS(MasterData[Semi-Annual Base],MasterData[Survivor Customer'#],AcctReport!C11) -> 0 | M11: =SUMIFS(MasterData[Semi-Annual Focus],MasterData[Survivor Customer'#],AcctReport!C11) -> 0 | N11: =SUMIFS(MasterData[Base Rebate],MasterData[Survivor Customer'#],AcctReport!C11) -> 1519.7501 | O11: =SUMIFS(MasterData[Annual Focus],MasterData[Survivor Customer'#],AcctReport!C11) -> 0 | P11: =SUMIFS(MasterData[Growth Rebate],MasterData[Survivor Customer'#],AcctReport!C11) -> 3390.176 | Q11: =SUM(L11:P11) -> 4909.9261
A12: MONTEFIORE HEALTH SYSTEM | B12: MONTEFIORE HEALTH SYSTEM | C12: 1001002565 | D12: MONTEFIORE WAKEFIELD HOSPITAL | E12: 600 E 233RD ST | F12: BRONX | G12: NY | H12: 10466 | I12: =SUMIFS(MasterData[Curr Sales],MasterData[Survivor Customer'#],AcctReport!C12) -> 173624.11 | J12: =SUMIFS(MasterData[Prior Sales],MasterData[Survivor Customer'#],AcctReport!C12) -> 187194.5 | K12: =+I12-J12 -> -13570.39 | L12: =SUMIFS(MasterData[Semi-Annual Base],MasterData[Survivor Customer'#],AcctReport!C12) -> 0 | M12: =SUMIFS(MasterData[Semi-Annual Focus],MasterData[Survivor Customer'#],AcctReport!C12) -> 0 | N12: =SUMIFS(MasterData[Base Rebate],MasterData[Survivor Customer'#],AcctReport!C12) -> 1441.9197 | O12: =SUMIFS(MasterData[Annual Focus],MasterData[Survivor Customer'#],AcctReport!C12) -> 0 | P12: =SUMIFS(MasterData[Growth Rebate],MasterData[Survivor Customer'#],AcctReport!C12) -> -1357.039 | Q12: =SUM(L12:P12) -> 84.88073
A13: MONTEFIORE HEALTH SYSTEM | B13: MONTEFIORE HEALTH SYSTEM | C13: 1001003152 | D13: NYACK HOSPITAL | E13: 160 N MIDLAND AVE | F13: NYACK | G13: NY | H13: 10960 | I13: =SUMIFS(MasterData[Curr Sales],MasterData[Survivor Customer'#],AcctReport!C13) -> 2053061 | J13: =SUMIFS(MasterData[Prior Sales],MasterData[Survivor Customer'#],AcctReport!C13) -> 1676179.1 | K13: =+I13-J13 -> 376881.87 | L13: =SUMIFS(MasterData[Semi-Annual Base],MasterData[Survivor Customer'#],AcctReport!C13) -> 0 | M13: =SUMIFS(MasterData[Semi-Annual Focus],MasterData[Survivor Customer'#],AcctReport!C13) -> 0 | N13: =SUMIFS(MasterData[Base Rebate],MasterData[Survivor Customer'#],AcctReport!C13) -> 12911.254 | O13: =SUMIFS(MasterData[Annual Focus],MasterData[Survivor Customer'#],AcctReport!C13) -> 0 | P13: =SUMIFS(MasterData[Growth Rebate],MasterData[Survivor Customer'#],AcctReport!C13) -> 37688.187 | Q13: =SUM(L13:P13) -> 50599.441
A14: MONTEFIORE HEALTH SYSTEM | B14: MONTEFIORE HEALTH SYSTEM | C14: 1001005131 | D14: ALBERT EINSTEIN COLLEGE OF MEDICINE | E14: 1300 MORRIS PARK AVE | F14: BRONX | G14: NY | H14: 10461 | I14: =SUMIFS(MasterData[Curr Sales],MasterData[Survivor Customer'#],AcctReport!C14) -> 35033.61 | J14: =SUMIFS(MasterData[Prior Sales],MasterData[Survivor Customer'#],AcctReport!C14) -> 45726.21 | K14: =+I14-J14 -> -10692.6 | L14: =SUMIFS(MasterData[Semi-Annual Base],MasterData[Survivor Customer'#],AcctReport!C14) -> 0 | M14: =SUMIFS(MasterData[Semi-Annual Focus],MasterData[Survivor Customer'#],AcctReport!C14) -> 0 | N14: =SUMIFS(MasterData[Base Rebate],MasterData[Survivor Customer'#],AcctReport!C14) -> 352.21935 | O14: =SUMIFS(MasterData[Annual Focus],MasterData[Survivor Customer'#],AcctReport!C14) -> 0 | P14: =SUMIFS(MasterData[Growth Rebate],MasterData[Survivor Customer'#],AcctReport!C14) -> -1069.26 | Q14: =SUM(L14:P14) -> -717.04065
A15: MONTEFIORE HEALTH SYSTEM | B15: MONTEFIORE HEALTH SYSTEM | C15: 1001006241 | D15: SCARSDALE MEDICAL GROUP | E15: 259 HEATHCOTE RD | F15: SCARSDALE | G15: NY | H15: 10583 | I15: =SUMIFS(MasterData[Curr Sales],MasterData[Survivor Customer'#],AcctReport!C15) -> 9974.78 | J15: =SUMIFS(MasterData[Prior Sales],MasterData[Survivor Customer'#],AcctReport!C15) -> 5676.27 | K15: =+I15-J15 -> 4298.51 | L15: =SUMIFS(MasterData[Semi-Annual Base],MasterData[Survivor Customer'#],AcctReport!C15) -> 0 | M15: =SUMIFS(MasterData[Semi-Annual Focus],MasterData[Survivor Customer'#],AcctReport!C15) -> 0 | N15: =SUMIFS(MasterData[Base Rebate],MasterData[Survivor Customer'#],AcctReport!C15) -> 43.72311 | O15: =SUMIFS(MasterData[Annual Focus],MasterData[Survivor Customer'#],AcctReport!C15) -> 0 | P15: =SUMIFS(MasterData[Growth Rebate],MasterData[Survivor Customer'#],AcctReport!C15) -> 429.851 | Q15: =SUM(L15:P15) -> 473.57411
A16: MONTEFIORE HEALTH SYSTEM | B16: MONTEFIORE HEALTH SYSTEM | C16: 1001014969 | D16: MONTEFIORE MEDICAL CENTER | E16: 4341 BULLARD AVE | F16: BRONX | G16: NY | H16: 10466 | I16: =SUMIFS(MasterData[Curr Sales],MasterData[Survivor Customer'#],AcctReport!C16) -> 172991.92 | J16: =SUMIFS(MasterData[Prior Sales],MasterData[Survivor Customer'#],AcctReport!C16) -> 928373.34 | K16: =+I16-J16 -> -755381.42 | L16: =SUMIFS(MasterData[Semi-Annual Base],MasterData[Survivor Customer'#],AcctReport!C16) -> 0 | M16: =SUMIFS(MasterData[Semi-Annual Focus],MasterData[Survivor Customer'#],AcctReport!C16) -> 0 | N16: =SUMIFS(MasterData[Base Rebate],MasterData[Survivor Customer'#],AcctReport!C16) -> 7151.0639 | O16: =SUMIFS(MasterData[Annual Focus],MasterData[Survivor Customer'#],AcctReport!C16) -> 0 | P16: =SUMIFS(MasterData[Growth Rebate],MasterData[Survivor Customer'#],AcctReport!C16) -> -75538.142 | Q16: =SUM(L16:P16) -> -68387.078
A17: MONTEFIORE HEALTH SYSTEM | B17: MONTEFIORE HEALTH SYSTEM | C17: 1001014971 | D17: MONTEFIORE MEDICAL CENTER | E17: STEUBEN AVE AT GUNHILL RD | F17: BRONX | G17: NY | H17: 10467 | I17: =SUMIFS(MasterData[Curr Sales],MasterData[Survivor Customer'#],AcctReport!C17) -> 2301235.3 | J17: =SUMIFS(MasterData[Prior Sales],MasterData[Survivor Customer'#],AcctReport!C17) -> 1642239.1 | K17: =+I17-J17 -> 658996.18 | L17: =SUMIFS(MasterData[Semi-Annual Base],MasterData[Survivor Customer'#],AcctReport!C17) -> 0 | M17: =SUMIFS(MasterData[Semi-Annual Focus],MasterData[Survivor Customer'#],AcctReport!C17) -> 0 | N17: =SUMIFS(MasterData[Base Rebate],MasterData[Survivor Customer'#],AcctReport!C17) -> 12649.821 | O17: =SUMIFS(MasterData[Annual Focus],MasterData[Survivor Customer'#],AcctReport!C17) -> 0 | P17: =SUMIFS(MasterData[Growth Rebate],MasterData[Survivor Customer'#],AcctReport!C17) -> 65899.618 | Q17: =SUM(L17:P17) -> 78549.439
A18: MONTEFIORE HEALTH SYSTEM | B18: MONTEFIORE HEALTH SYSTEM | C18: 1001015235 | D18: MARBLE HILL FAMILY PRACTICE MONTEFIORE MEDICAL GROUP | E18: 5525 BROADWAY | F18: BRONX | G18: NY | H18: 10463 | I18: =SUMIFS(MasterData[Curr Sales],MasterData[Survivor Customer'#],AcctReport!C18) -> 13524.68 | J18: =SUMIFS(MasterData[Prior Sales],MasterData[Survivor Customer'#],AcctReport!C18) -> 14037.87 | K18: =+I18-J18 -> -513.19 | L18: =SUMIFS(MasterData[Semi-Annual Base],MasterData[Survivor Customer'#],AcctReport!C18) -> 0 | M18: =SUMIFS(MasterData[Semi-Annual Focus],MasterData[Survivor Customer'#],AcctReport!C18) -> 0 | N18: =SUMIFS(MasterData[Base Rebate],MasterData[Survivor Customer'#],AcctReport!C18) -> 108.13075 | O18: =SUMIFS(MasterData[Annual Focus],MasterData[Survivor Customer'#],AcctReport!C18) -> 0 | P18: =SUMIFS(MasterData[Growth Rebate],MasterData[Survivor Customer'#],AcctReport!C18) -> -51.319 | Q18: =SUM(L18:P18) -> 56.81175
A19: MONTEFIORE HEALTH SYSTEM | B19: MONTEFIORE HEALTH SYSTEM | C19: 1001017323 | D19: SCARSDALE MEDICAL GROUP | E19: 550 MAMARONECK AVE | F19: HARRISON | G19: NY | H19: 10528 | I19: =SUMIFS(MasterData[Curr Sales],MasterData[Survivor Customer'#],AcctReport!C19) -> 2381.8 | J19: =SUMIFS(MasterData[Prior Sales],MasterData[Survivor Customer'#],AcctReport!C19) -> 1135.36 | K19: =+I19-J19 -> 1246.44 | L19: =SUMIFS(MasterData[Semi-Annual Base],MasterData[Survivor Customer'#],AcctReport!C19) -> 0 | M19: =SUMIFS(MasterData[Semi-Annual Focus],MasterData[Survivor Customer'#],AcctReport!C19) -> 0 | N19: =SUMIFS(MasterData[Base Rebate],MasterData[Survivor Customer'#],AcctReport!C19) -> 8.7454385 | O19: =SUMIFS(MasterData[Annual Focus],MasterData[Survivor Customer'#],AcctReport!C19) -> 0 | P19: =SUMIFS(MasterData[Growth Rebate],MasterData[Survivor Customer'#],AcctReport!C19) -> 124.644 | Q19: =SUM(L19:P19) -> 133.38944
... A140: MONTEFIORE HEALTH SYSTEM | B140: MONTEFIORE HEALTH SYSTEM | C140: 50887808_JDE | D140: WHITE PLAINS HOSPITAL PHYSICIAN | E140: 2 OVERHILL RD STE 225 | F140: SCARSDALE | G140: NY | H140: 10583 | I140: =SUMIFS(MasterData[Curr Sales],MasterData[Survivor Customer'#],AcctReport!C140) -> 8.1 | J140: =SUMIFS(MasterData[Prior Sales],MasterData[Survivor Customer'#],AcctReport!C140) -> 0 | K140: =+I140-J140 -> 8.1 | L140: =SUMIFS(MasterData[Semi-Annual Base],MasterData[Survivor Customer'#],AcctReport!C140) -> 0 | M140: =SUMIFS(MasterData[Semi-Annual Focus],MasterData[Survivor Customer'#],AcctReport!C140) -> 0 | N140: =SUMIFS(MasterData[Base Rebate],MasterData[Survivor Customer'#],AcctReport!C140) -> 0 | O140: =SUMIFS(MasterData[Annual Focus],MasterData[Survivor Customer'#],AcctReport!C140) -> 0 | P140: =SUMIFS(MasterData[Growth Rebate],MasterData[Survivor Customer'#],AcctReport!C140) -> 0.81 | Q140: =SUM(L140:P140) -> 0.81
I141: =SUMIFS(MasterData[Curr Sales],MasterData[Survivor Customer'#],AcctReport!C141) -> 0 | J141: =SUMIFS(MasterData[Prior Sales],MasterData[Survivor Customer'#],AcctReport!C141) -> 0 | K141: =+I141-J141 -> 0 | L141: =SUMIFS(MasterData[Semi-Annual Base],MasterData[Survivor Customer'#],AcctReport!C141) -> 0 | M141: =SUMIFS(MasterData[Semi-Annual Focus],MasterData[Survivor Customer'#],AcctReport!C141) -> 0 | N141: =SUMIFS(MasterData[Base Rebate],MasterData[Survivor Customer'#],AcctReport!C141) -> 0 | O141: =SUMIFS(MasterData[Annual Focus],MasterData[Survivor Customer'#],AcctReport!C141) -> 0 | P141: =SUMIFS(MasterData[Growth Rebate],MasterData[Survivor Customer'#],AcctReport!C141) -> 0 | Q141: =SUM(L141:P141) -> 0
I142: =SUMIFS(MasterData[Curr Sales],MasterData[Survivor Customer'#],AcctReport!C142) -> 0 | J142: =SUMIFS(MasterData[Prior Sales],MasterData[Survivor Customer'#],AcctReport!C142) -> 0 | K142: =+I142-J142 -> 0 | L142: =SUMIFS(MasterData[Semi-Annual Base],MasterData[Survivor Customer'#],AcctReport!C142) -> 0 | M142: =SUMIFS(MasterData[Semi-Annual Focus],MasterData[Survivor Customer'#],AcctReport!C142) -> 0 | N142: =SUMIFS(MasterData[Base Rebate],MasterData[Survivor Customer'#],AcctReport!C142) -> 0 | O142: =SUMIFS(MasterData[Annual Focus],MasterData[Survivor Customer'#],AcctReport!C142) -> 0 | P142: =SUMIFS(MasterData[Growth Rebate],MasterData[Survivor Customer'#],AcctReport!C142) -> 0 | Q142: =SUM(L142:P142) -> 0
I143: =SUMIFS(MasterData[Curr Sales],MasterData[Survivor Customer'#],AcctReport!C143) -> 0 | J143: =SUMIFS(MasterData[Prior Sales],MasterData[Survivor Customer'#],AcctReport!C143) -> 0 | K143: =+I143-J143 -> 0 | L143: =SUMIFS(MasterData[Semi-Annual Base],MasterData[Survivor Customer'#],AcctReport!C143) -> 0 | M143: =SUMIFS(MasterData[Semi-Annual Focus],MasterData[Survivor Customer'#],AcctReport!C143) -> 0 | N143: =SUMIFS(MasterData[Base Rebate],MasterData[Survivor Customer'#],AcctReport!C143) -> 0 | O143: =SUMIFS(MasterData[Annual Focus],MasterData[Survivor Customer'#],AcctReport!C143) -> 0 | P143: =SUMIFS(MasterData[Growth Rebate],MasterData[Survivor Customer'#],AcctReport!C143) -> 0 | Q143: =SUM(L143:P143) -> 0
I144: =SUMIFS(MasterData[Curr Sales],MasterData[Survivor Customer'#],AcctReport!C144) -> 0 | J144: =SUMIFS(MasterData[Prior Sales],MasterData[Survivor Customer'#],AcctReport!C144) -> 0 | K144: =+I144-J144 -> 0 | L144: =SUMIFS(MasterData[Semi-Annual Base],MasterData[Survivor Customer'#],AcctReport!C144) -> 0 | M144: =SUMIFS(MasterData[Semi-Annual Focus],MasterData[Survivor Customer'#],AcctReport!C144) -> 0 | N144: =SUMIFS(MasterData[Base Rebate],MasterData[Survivor Customer'#],AcctReport!C144) -> 0 | O144: =SUMIFS(MasterData[Annual Focus],MasterData[Survivor Customer'#],AcctReport!C144) -> 0 | P144: =SUMIFS(MasterData[Growth Rebate],MasterData[Survivor Customer'#],AcctReport!C144) -> 0 | Q144: =SUM(L144:P144) -> 0
I145: =SUMIFS(MasterData[Curr Sales],MasterData[Survivor Customer'#],AcctReport!C145) -> 0 | J145: =SUMIFS(MasterData[Prior Sales],MasterData[Survivor Customer'#],AcctReport!C145) -> 0 | K145: =+I145-J145 -> 0 | L145: =SUMIFS(MasterData[Semi-Annual Base],MasterData[Survivor Customer'#],AcctReport!C145) -> 0 | M145: =SUMIFS(MasterData[Semi-Annual Focus],MasterData[Survivor Customer'#],AcctReport!C145) -> 0 | N145: =SUMIFS(MasterData[Base Rebate],MasterData[Survivor Customer'#],AcctReport!C145) -> 0 | O145: =SUMIFS(MasterData[Annual Focus],MasterData[Survivor Customer'#],AcctReport!C145) -> 0 | P145: =SUMIFS(MasterData[Growth Rebate],MasterData[Survivor Customer'#],AcctReport!C145) -> 0 | Q145: =SUM(L145:P145) -> 0
I146: =SUMIFS(MasterData[Curr Sales],MasterData[Survivor Customer'#],AcctReport!C146) -> 0 | J146: =SUMIFS(MasterData[Prior Sales],MasterData[Survivor Customer'#],AcctReport!C146) -> 0 | K146: =+I146-J146 -> 0 | L146: =SUMIFS(MasterData[Semi-Annual Base],MasterData[Survivor Customer'#],AcctReport!C146) -> 0 | M146: =SUMIFS(MasterData[Semi-Annual Focus],MasterData[Survivor Customer'#],AcctReport!C146) -> 0 | N146: =SUMIFS(MasterData[Base Rebate],MasterData[Survivor Customer'#],AcctReport!C146) -> 0 | O146: =SUMIFS(MasterData[Annual Focus],MasterData[Survivor Customer'#],AcctReport!C146) -> 0 | P146: =SUMIFS(MasterData[Growth Rebate],MasterData[Survivor Customer'#],AcctReport!C146) -> 0 | Q146: =SUM(L146:P146) -> 0
I147: =SUMIFS(MasterData[Curr Sales],MasterData[Survivor Customer'#],AcctReport!C147) -> 0 | J147: =SUMIFS(MasterData[Prior Sales],MasterData[Survivor Customer'#],AcctReport!C147) -> 0 | K147: =+I147-J147 -> 0 | L147: =SUMIFS(MasterData[Semi-Annual Base],MasterData[Survivor Customer'#],AcctReport!C147) -> 0 | M147: =SUMIFS(MasterData[Semi-Annual Focus],MasterData[Survivor Customer'#],AcctReport!C147) -> 0 | N147: =SUMIFS(MasterData[Base Rebate],MasterData[Survivor Customer'#],AcctReport!C147) -> 0 | O147: =SUMIFS(MasterData[Annual Focus],MasterData[Survivor Customer'#],AcctReport!C147) -> 0 | P147: =SUMIFS(MasterData[Growth Rebate],MasterData[Survivor Customer'#],AcctReport!C147) -> 0 | Q147: =SUM(L147:P147) -> 0
I148: =SUMIFS(MasterData[Curr Sales],MasterData[Survivor Customer'#],AcctReport!C148) -> 0 | J148: =SUMIFS(MasterData[Prior Sales],MasterData[Survivor Customer'#],AcctReport!C148) -> 0 | K148: =+I148-J148 -> 0 | L148: =SUMIFS(MasterData[Semi-Annual Base],MasterData[Survivor Customer'#],AcctReport!C148) -> 0 | M148: =SUMIFS(MasterData[Semi-Annual Focus],MasterData[Survivor Customer'#],AcctReport!C148) -> 0 | N148: =SUMIFS(MasterData[Base Rebate],MasterData[Survivor Customer'#],AcctReport!C148) -> 0 | O148: =SUMIFS(MasterData[Annual Focus],MasterData[Survivor Customer'#],AcctReport!C148) -> 0 | P148: =SUMIFS(MasterData[Growth Rebate],MasterData[Survivor Customer'#],AcctReport!C148) -> 0 | Q148: =SUM(L148:P148) -> 0
I149: =SUMIFS(MasterData[Curr Sales],MasterData[Survivor Customer'#],AcctReport!C149) -> 0 | J149: =SUMIFS(MasterData[Prior Sales],MasterData[Survivor Customer'#],AcctReport!C149) -> 0 | K149: =+I149-J149 -> 0 | L149: =SUMIFS(MasterData[Semi-Annual Base],MasterData[Survivor Customer'#],AcctReport!C149) -> 0 | M149: =SUMIFS(MasterData[Semi-Annual Focus],MasterData[Survivor Customer'#],AcctReport!C149) -> 0 | N149: =SUMIFS(MasterData[Base Rebate],MasterData[Survivor Customer'#],AcctReport!C149) -> 0 | O149: =SUMIFS(MasterData[Annual Focus],MasterData[Survivor Customer'#],AcctReport!C149) -> 0 | P149: =SUMIFS(MasterData[Growth Rebate],MasterData[Survivor Customer'#],AcctReport!C149) -> 0 | Q149: =SUM(L149:P149) -> 0
I150: =SUMIFS(MasterData[Curr Sales],MasterData[Survivor Customer'#],AcctReport!C150) -> 0 | J150: =SUMIFS(MasterData[Prior Sales],MasterData[Survivor Customer'#],AcctReport!C150) -> 0 | K150: =+I150-J150 -> 0 | L150: =SUMIFS(MasterData[Semi-Annual Base],MasterData[Survivor Customer'#],AcctReport!C150) -> 0 | M150: =SUMIFS(MasterData[Semi-Annual Focus],MasterData[Survivor Customer'#],AcctReport!C150) -> 0 | N150: =SUMIFS(MasterData[Base Rebate],MasterData[Survivor Customer'#],AcctReport!C150) -> 0 | O150: =SUMIFS(MasterData[Annual Focus],MasterData[Survivor Customer'#],AcctReport!C150) -> 0 | P150: =SUMIFS(MasterData[Growth Rebate],MasterData[Survivor Customer'#],AcctReport!C150) -> 0 | Q150: =SUM(L150:P150) -> 0
I151: =SUMIFS(MasterData[Curr Sales],MasterData[Survivor Customer'#],AcctReport!C151) -> 0 | J151: =SUMIFS(MasterData[Prior Sales],MasterData[Survivor Customer'#],AcctReport!C151) -> 0 | K151: =+I151-J151 -> 0 | L151: =SUMIFS(MasterData[Semi-Annual Base],MasterData[Survivor Customer'#],AcctReport!C151) -> 0 | M151: =SUMIFS(MasterData[Semi-Annual Focus],MasterData[Survivor Customer'#],AcctReport!C151) -> 0 | N151: =SUMIFS(MasterData[Base Rebate],MasterData[Survivor Customer'#],AcctReport!C151) -> 0 | O151: =SUMIFS(MasterData[Annual Focus],MasterData[Survivor Customer'#],AcctReport!C151) -> 0 | P151: =SUMIFS(MasterData[Growth Rebate],MasterData[Survivor Customer'#],AcctReport!C151) -> 0 | Q151: =SUM(L151:P151) -> 0
I152: =SUMIFS(MasterData[Curr Sales],MasterData[Survivor Customer'#],AcctReport!C152) -> 0 | J152: =SUMIFS(MasterData[Prior Sales],MasterData[Survivor Customer'#],AcctReport!C152) -> 0 | K152: =+I152-J152 -> 0 | L152: =SUMIFS(MasterData[Semi-Annual Base],MasterData[Survivor Customer'#],AcctReport!C152) -> 0 | M152: =SUMIFS(MasterData[Semi-Annual Focus],MasterData[Survivor Customer'#],AcctReport!C152) -> 0 | N152: =SUMIFS(MasterData[Base Rebate],MasterData[Survivor Customer'#],AcctReport!C152) -> 0 | O152: =SUMIFS(MasterData[Annual Focus],MasterData[Survivor Customer'#],AcctReport!C152) -> 0 | P152: =SUMIFS(MasterData[Growth Rebate],MasterData[Survivor Customer'#],AcctReport!C152) -> 0 | Q152: =SUM(L152:P152) -> 0
... I476: =SUMIFS(MasterData[Curr Sales],MasterData[Survivor Customer'#],AcctReport!C476) -> 0 | J476: =SUMIFS(MasterData[Prior Sales],MasterData[Survivor Customer'#],AcctReport!C476) -> 0 | K476: =+I476-J476 -> 0 | L476: =SUMIFS(MasterData[Semi-Annual Base],MasterData[Survivor Customer'#],AcctReport!C476) -> 0 | M476: =SUMIFS(MasterData[Semi-Annual Focus],MasterData[Survivor Customer'#],AcctReport!C476) -> 0 | N476: =SUMIFS(MasterData[Base Rebate],MasterData[Survivor Customer'#],AcctReport!C476) -> 0 | O476: =SUMIFS(MasterData[Annual Focus],MasterData[Survivor Customer'#],AcctReport!C476) -> 0 | P476: =SUMIFS(MasterData[Growth Rebate],MasterData[Survivor Customer'#],AcctReport!C476) -> 0 | Q476: =SUM(L476:P476) -> 0

Sheet By Member
A1: ='Executive Summary'!B3 -> Strategic Collaboration Agreement
A2: =beneficiary -> MONTEFIORE HEALTH SYSTEM
A3: From | B3: {=TRANSPOSE(_xlfn.ANCHORARRAY('Executive Summary'!C8))} -> #REF! | M3: {='Executive Summary'!H16:L16} -> 0.015 | N3: 0 | O3: 0.015 | P3: 0 | Q3: 0.1
A4: To | I4: Total from Executive Summary | J4: ='Executive Summary'!D36 -> 29583190 | K4: ='Executive Summary'!E36 -> 26526170 | L4: =J4-K4 -> 3057019.9 | M4: =IF(MONTH(EndMonth)=12,0,'Executive Summary'!H36) -> 0 | N4: =IF(MONTH(EndMonth)=12,0,'Executive Summary'!I36) -> 0 | O4: {='Executive Summary'!J36:L36} -> 204325.49 | P4: 0 | Q4: 305701.99 | R4: =ROUND(SUM(M4:Q4),2) -> 510027.48
A5: Strategic IDN | B5: Strategic Division | C5: Survivor# | D5: Member | E5: Name | F5: Address | G5: City | H5: ST | I5: Zip | J5: Current | K5: Prior | L5: Variance | M5: Semi-Annual Base | N5: Semi-Annual Focus Rebate | O5: Base Rebate | P5: Annual Focus Rebate | Q5: Growth Rebate | R5: Rebate
A6: MONTEFIORE HEALTH SYSTEM | B6: MONTEFIORE HEALTH SYSTEM | C6: 1001081884 | D6: AECOM | E6: ALBERT EINSTEIN COLLEGE | F6: 1301 MORRIS PARK AVE | G6: BRONX | H6: NY | I6: 10461 | J6: 4335.59 | K6: 2152.77 | L6: 2182.82 | M6: 0 | N6: 0 | O6: 16.582333 | P6: 0 | Q6: 218.282 | R6: 234.86433
A7: MONTEFIORE HEALTH SYSTEM | B7: MONTEFIORE HEALTH SYSTEM | C7: 1001005131 | D7: AECOM | E7: ALBERT EINSTEIN COLLEGE OF MEDICINE | F7: 1300 MORRIS PARK AVE | G7: BRONX | H7: NY | I7: 10461 | J7: 35033.61 | K7: 45726.21 | L7: -10692.6 | M7: 0 | N7: 0 | O7: 352.21935 | P7: 0 | Q7: -1069.26 | R7: -717.04065
A8: MONTEFIORE HEALTH SYSTEM | B8: MONTEFIORE HEALTH SYSTEM | C8: 1001196877 | D8: AECOM | E8: ALBERT EINSTEIN COLLEGE OF MEDICINE DOSA CLINIC | F8: 1510 WATERS PL | G8: BRONX | H8: NY | I8: 10461 | J8: 4227.17 | K8: 6933.69 | L8: -2706.52 | M8: 0 | N8: 0 | O8: 53.408751 | P8: 0 | Q8: -270.652 | R8: -217.24325
D9: AECOM Total | R9: =SUBTOTAL(9,R6:R8) -> -699.41957
A10: MONTEFIORE HEALTH SYSTEM | B10: MONTEFIORE HEALTH SYSTEM | C10: 1001035322 | D10: BURKE | E10: BURKE REHABILITATION HOSPITAL | F10: 785 MAMARONECK AVE | G10: WHITE PLAINS | H10: NY | I10: 10605 | J10: 37412.37 | K10: 29862.91 | L10: 7549.46 | M10: 0 | N10: 0 | O10: 230.02769 | P10: 0 | Q10: 754.946 | R10: 984.97369
A11: MONTEFIORE HEALTH SYSTEM | B11: MONTEFIORE HEALTH SYSTEM | C11: 1001112906 | D11: BURKE | E11: BURKE REHABILITATION HOSPITAL MEDICAL RSCH INST RECEIVING DEPT | F11: 785 MAMARONECK AVE | G11: WHITE PLAINS | H11: NY | I11: 10605 | J11: 1860 | K11: 0 | L11: 1860 | M11: 0 | N11: 0 | O11: 0 | P11: 0 | Q11: 186 | R11: 186
D12: BURKE Total | R12: =SUBTOTAL(9,R10:R11) -> 1170.9737
A13: MONTEFIORE HEALTH SYSTEM | B13: MONTEFIORE HEALTH SYSTEM | C13: 1001017760 | D13: MMC | E13: ALBERT EINSTEIN HOSPITAL | F13: 1600 TENBROECK AVE | G13: BRONX | H13: NY | I13: 10461 | J13: 744779.27 | K13: 735020.04 | L13: 9759.23 | M13: 0 | N13: 0 | O13: 5661.7043 | P13: 0 | Q13: 975.923 | R13: 6637.6273
A14: MONTEFIORE HEALTH SYSTEM | B14: MONTEFIORE HEALTH SYSTEM | C14: 1001036314 | D14: MMC | E14: BRONX EAST MEDICAL CENTER | F14: 2300 WESTCHESTER AVE | G14: BRONX | H14: NY | I14: 10462 | J14: 108212.1 | K14: 96122.63 | L14: 12089.47 | M14: 0 | N14: 0 | O14: 740.41233 | P14: 0 | Q14: 1208.947 | R14: 1949.3593
A15: MONTEFIORE HEALTH SYSTEM | B15: MONTEFIORE HEALTH SYSTEM | C15: 1001340122 | D15: MMC | E15: BRONX MEDICAL CARE CARDIAC | F15: 2814 MIDDLETOWN RD | G15: BRONX | H15: NY | I15: 10461 | J15: 0 | K15: 530.45 | L15: -530.45 | M15: 0 | N15: 0 | O15: 4.0859444 | P15: 0 | Q15: -53.045 | R15: -48.959056
A16: MONTEFIORE HEALTH SYSTEM | B16: MONTEFIORE HEALTH SYSTEM | C16: 1001039657 | D16: MMC | E16: COMPREHENSIVE FAMILY CARE | F16: 1621 EASTCHESTER RD | G16: BRONX | H16: NY | I16: 10461 | J16: 17428.33 | K16: 14097.67 | L16: 3330.66 | M16: 0 | N16: 0 | O16: 108.59138 | P16: 0 | Q16: 333.066 | R16: 441.65738
A17: MONTEFIORE HEALTH SYSTEM | B17: MONTEFIORE HEALTH SYSTEM | C17: 1001225483 | D17: MMC | E17: CROSS COUNTY MEDICAL CENTER | F17: 1010 CENTRAL PARK AVE | G17: YONKERS | H17: NY | I17: 10704 | J17: 47705 | K17: 19565.74 | L17: 28139.26 | M17: 0 | N17: 0 | O17: 150.71077 | P17: 0 | Q17: 2813.926 | R17: 2964.6368
A18: MONTEFIORE HEALTH SYSTEM | B18: MONTEFIORE HEALTH SYSTEM | C18: 1001018273 | D18: MMC | E18: FERNANDO J CAMACHO MD | F18: 60 E 208TH ST | G18: BRONX | H18: NY | I18: 10467 | J18: 5404.79 | K18: 4810.3 | L18: 594.49 | M18: 0 | N18: 0 | O18: 37.052726 | P18: 0 | Q18: 59.449 | R18: 96.501726
A19: MONTEFIORE HEALTH SYSTEM | B19: MONTEFIORE HEALTH SYSTEM | C19: 1001181565 | D19: MMC | E19: HELEN MAY MD | F19: 1578 WILLIAMSBRIDGE RD | G19: BRONX | H19: NY | I19: 10461 | J19: 8284.48 | K19: 6356.25 | L19: 1928.23 | M19: 0 | N19: 0 | O19: 48.960852 | P19: 0 | Q19: 192.823 | R19: 241.78385
A20: MONTEFIORE HEALTH SYSTEM | B20: MONTEFIORE HEALTH SYSTEM | C20: 1001448005 | D20: MMC | E20: HUTCHINSON MEDICAL SERVICES | F20: 1250 WATERS PL | G20: BRONX | H20: NY | I20: 10461 | J20: 6506.67 | K20: 17115.28 | L20: -10608.61 | M20: 0 | N20: 0 | O20: 131.83539 | P20: 0 | Q20: -1060.861 | R20: -929.02561
A21: MONTEFIORE HEALTH SYSTEM | B21: MONTEFIORE HEALTH SYSTEM | C21: 1001040825 | D21: MMC | E21: JD WEILER HOSPITAL EINSTEIN COLL | F21: 1825 EASTCHESTER RD | G21: BRONX | H21: NY | I21: 10461 | J21: 5904.99 | K21: 3529 | L21: 2375.99 | M21: 0 | N21: 0 | O21: 27.183142 | P21: 0 | Q21: 237.599 | R21: 264.78214
A22: MONTEFIORE HEALTH SYSTEM | B22: MONTEFIORE HEALTH SYSTEM | C22: 1002913601 | D22: MMC | E22: KIDNEY MEDICAL ASSOCIATES | F22: 34 MARCONI ST | G22: BRONX | H22: NY | I22: 10461 | J22: 353.86 | K22: 295.98 | L22: 57.88 | M22: 0 | N22: 0 | O22: 2.2798715 | P22: 0 | Q22: 5.788 | R22: 8.0678715
A23: MONTEFIORE HEALTH SYSTEM | B23: MONTEFIORE HEALTH SYSTEM | C23: 1001015235 | D23: MMC | E23: MARBLE HILL FAMILY PRACTICE MONTEFIORE MEDICAL GROUP | F23: 5525 BROADWAY | G23: BRONX | H23: NY | I23: 10463 | J23: 13524.68 | K23: 14037.87 | L23: -513.19 | M23: 0 | N23: 0 | O23: 108.13075 | P23: 0 | Q23: -51.319 | R23: 56.81175
A24: MONTEFIORE HEALTH SYSTEM | B24: MONTEFIORE HEALTH SYSTEM | C24: 1001088153 | D24: MMC | E24: MERCY COLLEGE | F24: 1200 WATERS PL | G24: BRONX | H24: NY | I24: 10461 | J24: 0 | K24: 397.64 | L24: -397.64 | M24: 0 | N24: 0 | O24: 3.062937 | P24: 0 | Q24: -39.764 | R24: -36.701063
... A96: MONTEFIORE HEALTH SYSTEM | B96: MONTEFIORE HEALTH SYSTEM | C96: 1001020425 | D96: MMC | E96: WESTCHESTER SQUARE HOSPITAL | F96: 2475 SAINT RAYMOND AVE | G96: BRONX | H96: NY | I96: 10461 | J96: 9019.2 | K96: 3652.15 | L96: 5367.05 | M96: 0 | N96: 0 | O96: 28.131741 | P96: 0 | Q96: 536.705 | R96: 564.83674
D97: MMC Total | R97: =SUBTOTAL(9,R13:R96) -> 319726.34
A98: MONTEFIORE HEALTH SYSTEM | B98: MONTEFIORE HEALTH SYSTEM | C98: 1001230940 | D98: MOUNT VERNON | E98: MT VERNON DIALYSIS | F98: 12 N 7TH AVE | G98: MOUNT VERNON | H98: NY | I98: 10550 | J98: 502.4 | K98: 474.25 | L98: 28.15 | M98: 0 | N98: 0 | O98: 3.6530477 | P98: 0 | Q98: 2.815 | R98: 6.4680477
A99: MONTEFIORE HEALTH SYSTEM | B99: MONTEFIORE HEALTH SYSTEM | C99: 1001001124 | D99: MOUNT VERNON | E99: MT VERNON HOSPITAL | F99: 12 N 7TH AVE | G99: MOUNT VERNON | H99: NY | I99: 10550 | J99: 231200.44 | K99: 197298.68 | L99: 33901.76 | M99: 0 | N99: 0 | O99: 1519.7501 | P99: 0 | Q99: 3390.176 | R99: 4909.9261
A100: MONTEFIORE HEALTH SYSTEM | B100: MONTEFIORE HEALTH SYSTEM | C100: 1001037142 | D100: MOUNT VERNON | E100: MT VERNON HOSPITAL | F100: 9 N 8TH AVE | G100: MOUNT VERNON | H100: NY | I100: 10550 | J100: 54969.3 | K100: 63864.8 | L100: -8895.5 | M100: 0 | N100: 0 | O100: 491.93708 | P100: 0 | Q100: -889.55 | R100: -397.61292
D101: MOUNT VERNON Total | R101: =SUBTOTAL(9,R98:R100) -> 4518.7812
A102: MONTEFIORE HEALTH SYSTEM | B102: MONTEFIORE HEALTH SYSTEM | C102: 1002478635 | D102: NEW ROCHELLE | E102: MONTEFIORE HEART CLINIC | F102: 20 CEDAR ST | G102: NEW ROCHELLE | H102: NY | I102: 10801 | J102: 14367.98 | K102: 16997.91 | L102: -2629.93 | M102: 0 | N102: 0 | O102: 130.93131 | P102: 0 | Q102: -262.993 | R102: -132.06169
A103: MONTEFIORE HEALTH SYSTEM | B103: MONTEFIORE HEALTH SYSTEM | C103: 1001177090 | D103: NEW ROCHELLE | E103: MONTEFIORE NEW ROCHELLE HOSPITAL | F103: 16 GUION PL | G103: NEW ROCHELLE | H103: NY | I103: 10801 | J103: 734004.28 | K103: 728164.62 | L103: 5839.66 | M103: 0 | N103: 0 | O103: 5608.8984 | P103: 0 | Q103: 583.966 | R103: 6192.8644
D104: NEW ROCHELLE Total | R104: =SUBTOTAL(9,R102:R103) -> 6060.8027
A105: MONTEFIORE HEALTH SYSTEM | B105: MONTEFIORE HEALTH SYSTEM | C105: 1001306884 | D105: NYACK | E105: MOSHE WEISS MD | F105: 258 OLD NYACK TPKE | G105: SPRING VALLEY | H105: NY | I105: 10977 | J105: 570.87 | K105: 407.37 | L105: 163.5 | M105: 0 | N105: 0 | O105: 3.1378851 | P105: 0 | Q105: 16.35 | R105: 19.487885
A106: MONTEFIORE HEALTH SYSTEM | B106: MONTEFIORE HEALTH SYSTEM | C106: 1001657695 | D106: NYACK | E106: NYACK HOSP HOME CARE | F106: ONE BLUE HILL PLZ | G106: PEARL RIVER | H106: NY | I106: 10965 | J106: 0 | K106: 236.4 | L106: -236.4 | M106: 0 | N106: 0 | O106: 1.8209393 | P106: 0 | Q106: -23.64 | R106: -21.819061
A107: MONTEFIORE HEALTH SYSTEM | B107: MONTEFIORE HEALTH SYSTEM | C107: 1001003152 | D107: NYACK | E107: NYACK HOSPITAL | F107: 160 N MIDLAND AVE | G107: NYACK | H107: NY | I107: 10960 | J107: 2053061 | K107: 1676179.1 | L107: 376881.87 | M107: 0 | N107: 0 | O107: 12911.254 | P107: 0 | Q107: 37688.187 | R107: 50599.441
A108: MONTEFIORE HEALTH SYSTEM | B108: MONTEFIORE HEALTH SYSTEM | C108: 1001096315 | D108: NYACK | E108: NYACK HOSPITAL HISTOLOGY DEPT | F108: 160 N MIDLAND AVE | G108: NYACK | H108: NY | I108: 10960 | J108: 7295.25 | K108: 0 | L108: 7295.25 | M108: 0 | N108: 0 | O108: 0 | P108: 0 | Q108: 729.525 | R108: 729.525
D109: NYACK Total | R109: =SUBTOTAL(9,R105:R108) -> 51326.635
A110: MONTEFIORE HEALTH SYSTEM | B110: MONTEFIORE HEALTH SYSTEM | C110: 1001000635 | D110: ST LUKE'S | E110: CORNWALL HOSPITAL | F110: 19 LAUREL AVE | G110: CORNWALL | H110: NY | I110: 12518 | J110: 22385.05 | K110: 16818.07 | L110: 5566.98 | M110: 0 | N110: 0 | O110: 129.54604 | P110: 0 | Q110: 556.698 | R110: 686.24404
A111: MONTEFIORE HEALTH SYSTEM | B111: MONTEFIORE HEALTH SYSTEM | C111: 1001064773 | D111: ST LUKE'S | E111: EASTERN ORANGE AMBULATORY | F111: 21 LAUREL AVE | G111: CORNWALL | H111: NY | I111: 12518 | J111: 4934.58 | K111: 10439.24 | L111: -5504.66 | M111: 0 | N111: 0 | O111: 80.411263 | P111: 0 | Q111: -550.466 | R111: -470.05474
...

Sheet Member Summary
A1: BD SCA Rebate (July2025-Dec2025)
A3: MEMBER | B3: REBATE ($)
A4: AECOM | B4: -699
A5: BURKE | B5: 1171
A6: MMC | B6: 319726
A7: MOUNT VERNON | B7: 4519
A8: NEW ROCHELLE | B8: 6061
A9: NYACK | B9: 51326
A10: ST LUKE'S | B10: 16352
A11: WHITE PLAINS | B11: 111571
B13: =SUM(B4:B12) -> 510027
A16: ACH Date: | B16: 46073
A17: ACH #: | B17: MPR0220265100274

Sheet ProductReport
A1: ='Executive Summary'!B3 -> Strategic Collaboration Agreement
A2: =beneficiary -> MONTEFIORE HEALTH SYSTEM
A3: From | B3: {=TRANSPOSE(_xlfn.ANCHORARRAY('Executive Summary'!C8))} -> #REF!
A4: To
K5: {='Executive Summary'!D36:F36} -> 29583190 | L5: 26526170 | M5: 3057019.9 | N5: =IF(MONTH(EndMonth)=12,0,'Executive Summary'!H36) -> 0 | O5: =IF(MONTH(EndMonth)=12,0,'Executive Summary'!I36) -> 0 | P5: {='Executive Summary'!J36:L36} -> 204325.49 | Q5: 0 | R5: 305701.99 | S5: =ROUND(SUM(N5:R5),2) -> 510027.48
K6: =SUM(K8:K4762) -> 29583190 | L6: =SUM(L7:L4761) -> 26526170 | M6: =SUM(M7:M4761) -> 3057019.9 | N6: =SUM(N7:N4761) -> 0 | O6: =SUM(O7:O4761) -> 0 | P6: =SUM(P7:P4761) -> 204325.49 | Q6: =SUM(Q7:Q4761) -> 0 | R6: =SUM(R7:R4761) -> 305701.99 | S6: =ROUND(SUM(S7:S4761),2) -> 510027.48
A7: Business Segment | B7: Business Unit | C7: WWB ID | D7: World Wide Business | E7: Strategy Center | F7: Product Line | G7: Product Set | H7: Material# | I7: Material | J7: Legacy Business | K7: Curr Sales | L7: Prior Sales | M7: Variance | N7: Semi-Annual Base | O7: Semi-Annual Focus Rebate | P7: Base Rebate | Q7: Annual Focus Rebate | R7: Growth Rebate | S7: Rebate
A8: {=_xlfn._xlws.SORT(_xlfn.UNIQUE(MasterData[[Business Segment]:[Legacy Business]]),2)} -> BD LIFE SCIENCES | B8: Diagnostic Solutions | C8: 127 | D8: Infection Prevention and Management | E8: Core Micro | F8: Transport | G8: OEM Swabs | H8: 220116 | I8: Cultureswab Plus Amies W/O Charc Single | J8: BD | K8: =SUMIFS(MasterData[Curr Sales],MasterData[Material'#],H8,MasterData[Material],I8,MasterData[WWB ID],C8) -> 5586.17 | L8: =SUMIFS(MasterData[Prior Sales],MasterData[Material'#],H8,MasterData[Material],I8,MasterData[WWB ID],C8) -> 5237.17 | M8: =K8-L8 -> 349 | N8: =SUMIFS(MasterData[Semi-Annual Base],MasterData[Material'#],H8,MasterData[Material],I8,MasterData[WWB ID],C8) -> 0 | O8: =SUMIFS(MasterData[Semi-Annual Focus],MasterData[Material'#],H8,MasterData[Material],I8,MasterData[WWB ID],C8) -> 0 | P8: =SUMIFS(MasterData[Base Rebate],MasterData[Material'#],H8,MasterData[Material],I8,MasterData[WWB ID],C8) -> 40.340815 | Q8: =SUMIFS(MasterData[Annual Focus],MasterData[Material'#],H8,MasterData[Material],I8,MasterData[WWB ID],C8) -> 0 | R8: =SUMIFS(MasterData[Growth Rebate],MasterData[Material'#],H8,MasterData[Material],I8,MasterData[WWB ID],C8) -> 34.9 | S8: =SUM(N8:R8) -> 75.240815
A9: BD LIFE SCIENCES | B9: Diagnostic Solutions | C9: 127 | D9: Infection Prevention and Management | E9: Core Micro | F9: Lab Reagents | G9: Droppers | H9: 261203 | I9: Dropper Catalase Reagent | J9: BD | K9: =SUMIFS(MasterData[Curr Sales],MasterData[Material'#],H9,MasterData[Material],I9,MasterData[WWB ID],C9) -> 984.94 | L9: =SUMIFS(MasterData[Prior Sales],MasterData[Material'#],H9,MasterData[Material],I9,MasterData[WWB ID],C9) -> 1283.5 | M9: =K9-L9 -> -298.56 | N9: =SUMIFS(MasterData[Semi-Annual Base],MasterData[Material'#],H9,MasterData[Material],I9,MasterData[WWB ID],C9) -> 0 | O9: =SUMIFS(MasterData[Semi-Annual Focus],MasterData[Material'#],H9,MasterData[Material],I9,MasterData[WWB ID],C9) -> 0 | P9: =SUMIFS(MasterData[Base Rebate],MasterData[Material'#],H9,MasterData[Material],I9,MasterData[WWB ID],C9) -> 9.8865296 | Q9: =SUMIFS(MasterData[Annual Focus],MasterData[Material'#],H9,MasterData[Material],I9,MasterData[WWB ID],C9) -> 0 | R9: =SUMIFS(MasterData[Growth Rebate],MasterData[Material'#],H9,MasterData[Material],I9,MasterData[WWB ID],C9) -> -29.856 | S9: =SUM(N9:R9) -> -19.96947
A10: BD LIFE SCIENCES | B10: Diagnostic Solutions | C10: 127 | D10: Infection Prevention and Management | E10: Core Micro | F10: Lab Reagents | G10: Stain Kits | H10: 212542 | I10: Bottle Gram Iodine Stabilized 250ml | J10: BD | K10: =SUMIFS(MasterData[Curr Sales],MasterData[Material'#],H10,MasterData[Material],I10,MasterData[WWB ID],C10) -> 4001.44 | L10: =SUMIFS(MasterData[Prior Sales],MasterData[Material'#],H10,MasterData[Material],I10,MasterData[WWB ID],C10) -> 3213.96 | M10: =K10-L10 -> 787.48 | N10: =SUMIFS(MasterData[Semi-Annual Base],MasterData[Material'#],H10,MasterData[Material],I10,MasterData[WWB ID],C10) -> 0 | O10: =SUMIFS(MasterData[Semi-Annual Focus],MasterData[Material'#],H10,MasterData[Material],I10,MasterData[WWB ID],C10) -> 0 | P10: =SUMIFS(MasterData[Base Rebate],MasterData[Material'#],H10,MasterData[Material],I10,MasterData[WWB ID],C10) -> 24.756456 | Q10: =SUMIFS(MasterData[Annual Focus],MasterData[Material'#],H10,MasterData[Material],I10,MasterData[WWB ID],C10) -> 0 | R10: =SUMIFS(MasterData[Growth Rebate],MasterData[Material'#],H10,MasterData[Material],I10,MasterData[WWB ID],C10) -> 78.748 | S10: =SUM(N10:R10) -> 103.50446
A11: BD LIFE SCIENCES | B11: Diagnostic Solutions | C11: 127 | D11: Infection Prevention and Management | E11: Core Micro | F11: Lab Reagents | G11: Stain Kits | H11: 212527 | I11: Bottle Gram Decolorizer 250ml | J11: BD | K11: =SUMIFS(MasterData[Curr Sales],MasterData[Material'#],H11,MasterData[Material],I11,MasterData[WWB ID],C11) -> 5003.8 | L11: =SUMIFS(MasterData[Prior Sales],MasterData[Material'#],H11,MasterData[Material],I11,MasterData[WWB ID],C11) -> 3833.72 | M11: =K11-L11 -> 1170.08 | N11: =SUMIFS(MasterData[Semi-Annual Base],MasterData[Material'#],H11,MasterData[Material],I11,MasterData[WWB ID],C11) -> 0 | O11: =SUMIFS(MasterData[Semi-Annual Focus],MasterData[Material'#],H11,MasterData[Material],I11,MasterData[WWB ID],C11) -> 0 | P11: =SUMIFS(MasterData[Base Rebate],MasterData[Material'#],H11,MasterData[Material],I11,MasterData[WWB ID],C11) -> 29.530336 | Q11: =SUMIFS(MasterData[Annual Focus],MasterData[Material'#],H11,MasterData[Material],I11,MasterData[WWB ID],C11) -> 0 | R11: =SUMIFS(MasterData[Growth Rebate],MasterData[Material'#],H11,MasterData[Material],I11,MasterData[WWB ID],C11) -> 117.008 | S11: =SUM(N11:R11) -> 146.53834
A12: BD LIFE SCIENCES | B12: Diagnostic Solutions | C12: 127 | D12: Infection Prevention and Management | E12: Core Micro | F12: Lab Reagents | G12: Stain Kits | H12: 212525 | I12: Bottle Gram Crystal Violet 250ml | J12: BD | K12: =SUMIFS(MasterData[Curr Sales],MasterData[Material'#],H12,MasterData[Material],I12,MasterData[WWB ID],C12) -> 2400.32 | L12: =SUMIFS(MasterData[Prior Sales],MasterData[Material'#],H12,MasterData[Material],I12,MasterData[WWB ID],C12) -> 1480.8 | M12: =K12-L12 -> 919.52 | N12: =SUMIFS(MasterData[Semi-Annual Base],MasterData[Material'#],H12,MasterData[Material],I12,MasterData[WWB ID],C12) -> 0 | O12: =SUMIFS(MasterData[Semi-Annual Focus],MasterData[Material'#],H12,MasterData[Material],I12,MasterData[WWB ID],C12) -> 0 | P12: =SUMIFS(MasterData[Base Rebate],MasterData[Material'#],H12,MasterData[Material],I12,MasterData[WWB ID],C12) -> 11.40629 | Q12: =SUMIFS(MasterData[Annual Focus],MasterData[Material'#],H12,MasterData[Material],I12,MasterData[WWB ID],C12) -> 0 | R12: =SUMIFS(MasterData[Growth Rebate],MasterData[Material'#],H12,MasterData[Material],I12,MasterData[WWB ID],C12) -> 91.952 | S12: =SUM(N12:R12) -> 103.35829
A13: BD LIFE SCIENCES | B13: Diagnostic Solutions | C13: 127 | D13: Infection Prevention and Management | E13: Core Micro | F13: Lab Reagents | G13: Stain Kits | H13: 212531 | I13: Bottle Gram Safranin 250ml | J13: BD | K13: =SUMIFS(MasterData[Curr Sales],MasterData[Material'#],H13,MasterData[Material],I13,MasterData[WWB ID],C13) -> 2290 | L13: =SUMIFS(MasterData[Prior Sales],MasterData[Material'#],H13,MasterData[Material],I13,MasterData[WWB ID],C13) -> 1558.88 | M13: =K13-L13 -> 731.12 | N13: =SUMIFS(MasterData[Semi-Annual Base],MasterData[Material'#],H13,MasterData[Material],I13,MasterData[WWB ID],C13) -> 0 | O13: =SUMIFS(MasterData[Semi-Annual Focus],MasterData[Material'#],H13,MasterData[Material],I13,MasterData[WWB ID],C13) -> 0 | P13: =SUMIFS(MasterData[Base Rebate],MasterData[Material'#],H13,MasterData[Material],I13,MasterData[WWB ID],C13) -> 12.007724 | Q13: =SUMIFS(MasterData[Annual Focus],MasterData[Material'#],H13,MasterData[Material],I13,MasterData[WWB ID],C13) -> 0 | R13: =SUMIFS(MasterData[Growth Rebate],MasterData[Material'#],H13,MasterData[Material],I13,MasterData[WWB ID],C13) -> 73.112 | S13: =SUM(N13:R13) -> 85.119724
A14: BD LIFE SCIENCES | B14: Diagnostic Solutions | C14: 127 | D14: Infection Prevention and Management | E14: Core Micro | F14: Lab Reagents | G14: Stain Kits | H14: 212515 | I14: Bottle Tb Auramine-Rhodamine T 250Ml | J14: BD | K14: =SUMIFS(MasterData[Curr Sales],MasterData[Material'#],H14,MasterData[Material],I14,MasterData[WWB ID],C14) -> 280.8 | L14: =SUMIFS(MasterData[Prior Sales],MasterData[Material'#],H14,MasterData[Material],I14,MasterData[WWB ID],C14) -> 1068.24 | M14: =K14-L14 -> -787.44 | N14: =SUMIFS(MasterData[Semi-Annual Base],MasterData[Material'#],H14,MasterData[Material],I14,MasterData[WWB ID],C14) -> 0 | O14: =SUMIFS(MasterData[Semi-Annual Focus],MasterData[Material'#],H14,MasterData[Material],I14,MasterData[WWB ID],C14) -> 0 | P14: =SUMIFS(MasterData[Base Rebate],MasterData[Material'#],H14,MasterData[Material],I14,MasterData[WWB ID],C14) -> 8.2284273 | Q14: =SUMIFS(MasterData[Annual Focus],MasterData[Material'#],H14,MasterData[Material],I14,MasterData[WWB ID],C14) -> 0 | R14: =SUMIFS(MasterData[Growth Rebate],MasterData[Material'#],H14,MasterData[Material],I14,MasterData[WWB ID],C14) -> -78.744 | S14: =SUM(N14:R14) -> -70.515573
A15: BD LIFE SCIENCES | B15: Diagnostic Solutions | C15: 127 | D15: Infection Prevention and Management | E15: Core Micro | F15: Lab Reagents | G15: Stain Kits | H15: 212522 | I15: Kit Tb Stain Kit K | J15: BD | K15: =SUMIFS(MasterData[Curr Sales],MasterData[Material'#],H15,MasterData[Material],I15,MasterData[WWB ID],C15) -> 943.32 | L15: =SUMIFS(MasterData[Prior Sales],MasterData[Material'#],H15,MasterData[Material],I15,MasterData[WWB ID],C15) -> 1017.36 | M15: =K15-L15 -> -74.04 | N15: =SUMIFS(MasterData[Semi-Annual Base],MasterData[Material'#],H15,MasterData[Material],I15,MasterData[WWB ID],C15) -> 0 | O15: =SUMIFS(MasterData[Semi-Annual Focus],MasterData[Material'#],H15,MasterData[Material],I15,MasterData[WWB ID],C15) -> 0 | P15: =SUMIFS(MasterData[Base Rebate],MasterData[Material'#],H15,MasterData[Material],I15,MasterData[WWB ID],C15) -> 7.8365094 | Q15: =SUMIFS(MasterData[Annual Focus],MasterData[Material'#],H15,MasterData[Material],I15,MasterData[WWB ID],C15) -> 0 | R15: =SUMIFS(MasterData[Growth Rebate],MasterData[Material'#],H15,MasterData[Material],I15,MasterData[WWB ID],C15) -> -7.404 | S15: =SUM(N15:R15) -> 0.43250939
A16: BD LIFE SCIENCES | B16: Diagnostic Solutions | C16: 127 | D16: Infection Prevention and Management | E16: Core Micro | F16: Transport | G16: OEM Swabs | H16: 220220 | I16: Vial Universal Viral Transport | J16: BD | K16: =SUMIFS(MasterData[Curr Sales],MasterData[Material'#],H16,MasterData[Material],I16,MasterData[WWB ID],C16) -> 25689.75 | L16: =SUMIFS(MasterData[Prior Sales],MasterData[Material'#],H16,MasterData[Material],I16,MasterData[WWB ID],C16) -> 35113.43 | M16: =K16-L16 -> -9423.68 | N16: =SUMIFS(MasterData[Semi-Annual Base],MasterData[Material'#],H16,MasterData[Material],I16,MasterData[WWB ID],C16) -> 0 | O16: =SUMIFS(MasterData[Semi-Annual Focus],MasterData[Material'#],H16,MasterData[Material],I16,MasterData[WWB ID],C16) -> 0 | P16: =SUMIFS(MasterData[Base Rebate],MasterData[Material'#],H16,MasterData[Material],I16,MasterData[WWB ID],C16) -> 270.47134 | Q16: =SUMIFS(MasterData[Annual Focus],MasterData[Material'#],H16,MasterData[Material],I16,MasterData[WWB ID],C16) -> 0 | R16: =SUMIFS(MasterData[Growth Rebate],MasterData[Material'#],H16,MasterData[Material],I16,MasterData[WWB ID],C16) -> -942.368 | S16: =SUM(N16:R16) -> -671.89666
A17: BD LIFE SCIENCES | B17: Diagnostic Solutions | C17: 127 | D17: Infection Prevention and Management | E17: Core Micro | F17: Transport | G17: OEM Swabs | H17: 220531 | I17: Kit Uvt 3Ml With Flocked Flex Minitip | J17: BD | K17: =SUMIFS(MasterData[Curr Sales],MasterData[Material'#],H17,MasterData[Material],I17,MasterData[WWB ID],C17) -> 232088.64 | L17: =SUMIFS(MasterData[Prior Sales],MasterData[Material'#],H17,MasterData[Material],I17,MasterData[WWB ID],C17) -> 266978.64 | M17: =K17-L17 -> -34890 | N17: =SUMIFS(MasterData[Semi-Annual Base],MasterData[Material'#],H17,MasterData[Material],I17,MasterData[WWB ID],C17) -> 0 | O17: =SUMIFS(MasterData[Semi-Annual Focus],MasterData[Material'#],H17,MasterData[Material],I17,MasterData[WWB ID],C17) -> 0 | P17: =SUMIFS(MasterData[Base Rebate],MasterData[Material'#],H17,MasterData[Material],I17,MasterData[WWB ID],C17) -> 2056.4801 | Q17: =SUMIFS(MasterData[Annual Focus],MasterData[Material'#],H17,MasterData[Material],I17,MasterData[WWB ID],C17) -> 0 | R17: =SUMIFS(MasterData[Growth Rebate],MasterData[Material'#],H17,MasterData[Material],I17,MasterData[WWB ID],C17) -> -3489 | S17: =SUM(N17:R17) -> -1432.5199
A18: BD LIFE SCIENCES | B18: Diagnostic Solutions | C18: 127 | D18: Infection Prevention and Management | E18: Core Micro | F18: Transport | G18: OEM Swabs | H18: 220109 | I18: Cultureswab Liquid Stuart Double Swab | J18: BD | K18: =SUMIFS(MasterData[Curr Sales],MasterData[Material'#],H18,MasterData[Material],I18,MasterData[WWB ID],C18) -> 10316.49 | L18: =SUMIFS(MasterData[Prior Sales],MasterData[Material'#],H18,MasterData[Material],I18,MasterData[WWB ID],C18) -> 13667.96 | M18: =K18-L18 -> -3351.47 | N18: =SUMIFS(MasterData[Semi-Annual Base],MasterData[Material'#],H18,MasterData[Material],I18,MasterData[WWB ID],C18) -> 0 | O18: =SUMIFS(MasterData[Semi-Annual Focus],MasterData[Material'#],H18,MasterData[Material],I18,MasterData[WWB ID],C18) -> 0 | P18: =SUMIFS(MasterData[Base Rebate],MasterData[Material'#],H18,MasterData[Material],I18,MasterData[WWB ID],C18) -> 105.28141 | Q18: =SUMIFS(MasterData[Annual Focus],MasterData[Material'#],H18,MasterData[Material],I18,MasterData[WWB ID],C18) -> 0 | R18: =SUMIFS(MasterData[Growth Rebate],MasterData[Material'#],H18,MasterData[Material],I18,MasterData[WWB ID],C18) -> -335.147 | S18: =SUM(N18:R18) -> -229.86559
